{
 "cells": [
  {
   "cell_type": "code",
   "execution_count": 1,
   "metadata": {},
   "outputs": [
    {
     "name": "stderr",
     "output_type": "stream",
     "text": [
      "<>:18: SyntaxWarning: invalid escape sequence '\\s'\n",
      "<>:18: SyntaxWarning: invalid escape sequence '\\s'\n",
      "C:\\Users\\ldwen\\AppData\\Local\\Temp\\ipykernel_23308\\460620488.py:18: SyntaxWarning: invalid escape sequence '\\s'\n",
      "  data['text'] = data['text'].apply((lambda x: re.sub('[^a-zA-z0-9\\s]', '', x)))\n",
      "C:\\Users\\ldwen\\AppData\\Local\\Temp\\ipykernel_23308\\460620488.py:21: FutureWarning: Series.__getitem__ treating keys as positions is deprecated. In a future version, integer keys will always be treated as labels (consistent with DataFrame behavior). To access a value by position, use `ser.iloc[pos]`\n",
      "  row[0] = row[0].replace('rt', ' ')\n",
      "C:\\Users\\ldwen\\AppData\\Local\\Temp\\ipykernel_23308\\460620488.py:21: FutureWarning: Series.__setitem__ treating keys as positions is deprecated. In a future version, integer keys will always be treated as labels (consistent with DataFrame behavior). To set a value by position, use `ser.iloc[pos] = value`\n",
      "  row[0] = row[0].replace('rt', ' ')\n",
      "c:\\Users\\ldwen\\AppData\\Local\\Programs\\Python\\Python312\\Lib\\site-packages\\keras\\src\\layers\\core\\embedding.py:90: UserWarning: Argument `input_length` is deprecated. Just remove it.\n",
      "  warnings.warn(\n"
     ]
    },
    {
     "name": "stdout",
     "output_type": "stream",
     "text": [
      "291/291 - 7s - 25ms/step - accuracy: 0.6413 - loss: 0.8292\n",
      "144/144 - 1s - 8ms/step - accuracy: 0.6656 - loss: 0.7672\n",
      "0.7671765685081482\n",
      "0.6655744910240173\n",
      "['loss', 'compile_metrics']\n"
     ]
    }
   ],
   "source": [
    "import pandas as pd # data processing, CSV file I/O (e.g. pd.read_csv)\n",
    "from tensorflow.keras.preprocessing.text import Tokenizer\n",
    "from keras.preprocessing.sequence import pad_sequences\n",
    "from keras.models import Sequential\n",
    "from keras.layers import Dense, Embedding, LSTM, SpatialDropout1D\n",
    "from matplotlib import pyplot\n",
    "from sklearn.model_selection import train_test_split\n",
    "from tensorflow.keras.utils import to_categorical\n",
    "import re\n",
    "\n",
    "from sklearn.preprocessing import LabelEncoder\n",
    "\n",
    "data = pd.read_csv('Sentiment.csv')\n",
    "# Keeping only the neccessary columns\n",
    "data = data[['text','sentiment']]\n",
    "\n",
    "data['text'] = data['text'].apply(lambda x: x.lower())\n",
    "data['text'] = data['text'].apply((lambda x: re.sub('[^a-zA-z0-9\\s]', '', x)))\n",
    "\n",
    "for idx, row in data.iterrows():\n",
    "    row[0] = row[0].replace('rt', ' ')\n",
    "\n",
    "max_fatures = 2000\n",
    "tokenizer = Tokenizer(num_words=max_fatures, split=' ')\n",
    "tokenizer.fit_on_texts(data['text'].values)\n",
    "X = tokenizer.texts_to_sequences(data['text'].values)\n",
    "\n",
    "X = pad_sequences(X)\n",
    "\n",
    "embed_dim = 128\n",
    "lstm_out = 196\n",
    "def createmodel():\n",
    "    model = Sequential()\n",
    "    model.add(Embedding(max_fatures, embed_dim,input_length = X.shape[1]))\n",
    "    model.add(LSTM(lstm_out, dropout=0.2, recurrent_dropout=0.2))\n",
    "    model.add(Dense(3,activation='softmax'))\n",
    "    model.compile(loss = 'categorical_crossentropy', optimizer='adam',metrics = ['accuracy'])\n",
    "    return model\n",
    "# print(model.summary())\n",
    "\n",
    "labelencoder = LabelEncoder()\n",
    "integer_encoded = labelencoder.fit_transform(data['sentiment'])\n",
    "y = to_categorical(integer_encoded)\n",
    "X_train, X_test, Y_train, Y_test = train_test_split(X,y, test_size = 0.33, random_state = 42)\n",
    "\n",
    "batch_size = 32\n",
    "model = createmodel()\n",
    "model.fit(X_train, Y_train, epochs = 1, batch_size=batch_size, verbose = 2)\n",
    "score,acc = model.evaluate(X_test,Y_test,verbose=2,batch_size=batch_size)\n",
    "print(score)\n",
    "print(acc)\n",
    "print(model.metrics_names)\n"
   ]
  },
  {
   "cell_type": "markdown",
   "metadata": {},
   "source": [
    "### 1"
   ]
  },
  {
   "cell_type": "code",
   "execution_count": 2,
   "metadata": {},
   "outputs": [],
   "source": [
    "model.save(\"sentiment_analysis.keras\")"
   ]
  },
  {
   "cell_type": "code",
   "execution_count": 3,
   "metadata": {},
   "outputs": [
    {
     "name": "stdout",
     "output_type": "stream",
     "text": [
      "\u001b[1m1/1\u001b[0m \u001b[32m━━━━━━━━━━━━━━━━━━━━\u001b[0m\u001b[37m\u001b[0m \u001b[1m0s\u001b[0m 216ms/step\n"
     ]
    },
    {
     "data": {
      "text/plain": [
       "array([[0.5272558 , 0.1306929 , 0.34205133]], dtype=float32)"
      ]
     },
     "execution_count": 3,
     "metadata": {},
     "output_type": "execute_result"
    }
   ],
   "source": [
    "from tensorflow.keras.models import load_model\n",
    "model = load_model(\"sentiment_analysis.keras\")\n",
    "\n",
    "text = 'I really like this class, and I believe that I can get a good grade.'.lower()\n",
    "sequence = tokenizer.texts_to_sequences([text])\n",
    "padded_sequence = pad_sequences(sequence)\n",
    "\n",
    "model.predict(padded_sequence)"
   ]
  },
  {
   "cell_type": "markdown",
   "metadata": {},
   "source": [
    "### 2"
   ]
  },
  {
   "cell_type": "code",
   "execution_count": 25,
   "metadata": {},
   "outputs": [],
   "source": [
    "def createmodel(optimizer='adam'):\n",
    "    model = Sequential()\n",
    "    model.add(Embedding(max_fatures, 128))\n",
    "    model.add(LSTM(lstm_out, dropout=.2, recurrent_dropout=.2))\n",
    "    model.add(Dense(3, activation='softmax'))\n",
    "    model.compile(loss='categorical_crossentropy', optimizer=optimizer, metrics=['accuracy'])\n",
    "    return model"
   ]
  },
  {
   "cell_type": "code",
   "execution_count": 26,
   "metadata": {},
   "outputs": [],
   "source": [
    "from scikeras.wrappers import KerasClassifier\n",
    "from sklearn.model_selection import GridSearchCV\n",
    "\n",
    "model = KerasClassifier(model=createmodel, epochs=2, batch_size=32)\n",
    "\n",
    "parameters = {\n",
    "    'optimizer': ['adam', 'rmsprop'],\n",
    "}"
   ]
  },
  {
   "cell_type": "code",
   "execution_count": 27,
   "metadata": {},
   "outputs": [
    {
     "ename": "ValueError",
     "evalue": "\nAll the 10 fits failed.\nIt is very likely that your model is misconfigured.\nYou can try to debug the error by setting error_score='raise'.\n\nBelow are more details about the failures:\n--------------------------------------------------------------------------------\n1 fits failed with the following error:\nTraceback (most recent call last):\n  File \"c:\\Users\\ldwen\\AppData\\Local\\Programs\\Python\\Python312\\Lib\\site-packages\\sklearn\\model_selection\\_validation.py\", line 888, in _fit_and_score\n    estimator.fit(X_train, y_train, **fit_params)\n  File \"c:\\Users\\ldwen\\AppData\\Local\\Programs\\Python\\Python312\\Lib\\site-packages\\scikeras\\wrappers.py\", line 1501, in fit\n    super().fit(X=X, y=y, sample_weight=sample_weight, **kwargs)\n  File \"c:\\Users\\ldwen\\AppData\\Local\\Programs\\Python\\Python312\\Lib\\site-packages\\scikeras\\wrappers.py\", line 770, in fit\n    self._fit(\n  File \"c:\\Users\\ldwen\\AppData\\Local\\Programs\\Python\\Python312\\Lib\\site-packages\\scikeras\\wrappers.py\", line 936, in _fit\n    self._check_model_compatibility(y)\n  File \"c:\\Users\\ldwen\\AppData\\Local\\Programs\\Python\\Python312\\Lib\\site-packages\\scikeras\\wrappers.py\", line 559, in _check_model_compatibility\n    if self.n_outputs_expected_ != len(self.model_.outputs):\n                                       ^^^^^^^^^^^^^^^^^^^\n  File \"c:\\Users\\ldwen\\AppData\\Local\\Programs\\Python\\Python312\\Lib\\site-packages\\keras\\src\\models\\sequential.py\", line 300, in outputs\n    raise AttributeError(\nAttributeError: Sequential model 'sequential_91' has no defined outputs yet.\n\n--------------------------------------------------------------------------------\n1 fits failed with the following error:\nTraceback (most recent call last):\n  File \"c:\\Users\\ldwen\\AppData\\Local\\Programs\\Python\\Python312\\Lib\\site-packages\\sklearn\\model_selection\\_validation.py\", line 888, in _fit_and_score\n    estimator.fit(X_train, y_train, **fit_params)\n  File \"c:\\Users\\ldwen\\AppData\\Local\\Programs\\Python\\Python312\\Lib\\site-packages\\scikeras\\wrappers.py\", line 1501, in fit\n    super().fit(X=X, y=y, sample_weight=sample_weight, **kwargs)\n  File \"c:\\Users\\ldwen\\AppData\\Local\\Programs\\Python\\Python312\\Lib\\site-packages\\scikeras\\wrappers.py\", line 770, in fit\n    self._fit(\n  File \"c:\\Users\\ldwen\\AppData\\Local\\Programs\\Python\\Python312\\Lib\\site-packages\\scikeras\\wrappers.py\", line 936, in _fit\n    self._check_model_compatibility(y)\n  File \"c:\\Users\\ldwen\\AppData\\Local\\Programs\\Python\\Python312\\Lib\\site-packages\\scikeras\\wrappers.py\", line 559, in _check_model_compatibility\n    if self.n_outputs_expected_ != len(self.model_.outputs):\n                                       ^^^^^^^^^^^^^^^^^^^\n  File \"c:\\Users\\ldwen\\AppData\\Local\\Programs\\Python\\Python312\\Lib\\site-packages\\keras\\src\\models\\sequential.py\", line 300, in outputs\n    raise AttributeError(\nAttributeError: Sequential model 'sequential_92' has no defined outputs yet.\n\n--------------------------------------------------------------------------------\n1 fits failed with the following error:\nTraceback (most recent call last):\n  File \"c:\\Users\\ldwen\\AppData\\Local\\Programs\\Python\\Python312\\Lib\\site-packages\\sklearn\\model_selection\\_validation.py\", line 888, in _fit_and_score\n    estimator.fit(X_train, y_train, **fit_params)\n  File \"c:\\Users\\ldwen\\AppData\\Local\\Programs\\Python\\Python312\\Lib\\site-packages\\scikeras\\wrappers.py\", line 1501, in fit\n    super().fit(X=X, y=y, sample_weight=sample_weight, **kwargs)\n  File \"c:\\Users\\ldwen\\AppData\\Local\\Programs\\Python\\Python312\\Lib\\site-packages\\scikeras\\wrappers.py\", line 770, in fit\n    self._fit(\n  File \"c:\\Users\\ldwen\\AppData\\Local\\Programs\\Python\\Python312\\Lib\\site-packages\\scikeras\\wrappers.py\", line 936, in _fit\n    self._check_model_compatibility(y)\n  File \"c:\\Users\\ldwen\\AppData\\Local\\Programs\\Python\\Python312\\Lib\\site-packages\\scikeras\\wrappers.py\", line 559, in _check_model_compatibility\n    if self.n_outputs_expected_ != len(self.model_.outputs):\n                                       ^^^^^^^^^^^^^^^^^^^\n  File \"c:\\Users\\ldwen\\AppData\\Local\\Programs\\Python\\Python312\\Lib\\site-packages\\keras\\src\\models\\sequential.py\", line 300, in outputs\n    raise AttributeError(\nAttributeError: Sequential model 'sequential_93' has no defined outputs yet.\n\n--------------------------------------------------------------------------------\n1 fits failed with the following error:\nTraceback (most recent call last):\n  File \"c:\\Users\\ldwen\\AppData\\Local\\Programs\\Python\\Python312\\Lib\\site-packages\\sklearn\\model_selection\\_validation.py\", line 888, in _fit_and_score\n    estimator.fit(X_train, y_train, **fit_params)\n  File \"c:\\Users\\ldwen\\AppData\\Local\\Programs\\Python\\Python312\\Lib\\site-packages\\scikeras\\wrappers.py\", line 1501, in fit\n    super().fit(X=X, y=y, sample_weight=sample_weight, **kwargs)\n  File \"c:\\Users\\ldwen\\AppData\\Local\\Programs\\Python\\Python312\\Lib\\site-packages\\scikeras\\wrappers.py\", line 770, in fit\n    self._fit(\n  File \"c:\\Users\\ldwen\\AppData\\Local\\Programs\\Python\\Python312\\Lib\\site-packages\\scikeras\\wrappers.py\", line 936, in _fit\n    self._check_model_compatibility(y)\n  File \"c:\\Users\\ldwen\\AppData\\Local\\Programs\\Python\\Python312\\Lib\\site-packages\\scikeras\\wrappers.py\", line 559, in _check_model_compatibility\n    if self.n_outputs_expected_ != len(self.model_.outputs):\n                                       ^^^^^^^^^^^^^^^^^^^\n  File \"c:\\Users\\ldwen\\AppData\\Local\\Programs\\Python\\Python312\\Lib\\site-packages\\keras\\src\\models\\sequential.py\", line 300, in outputs\n    raise AttributeError(\nAttributeError: Sequential model 'sequential_94' has no defined outputs yet.\n\n--------------------------------------------------------------------------------\n1 fits failed with the following error:\nTraceback (most recent call last):\n  File \"c:\\Users\\ldwen\\AppData\\Local\\Programs\\Python\\Python312\\Lib\\site-packages\\sklearn\\model_selection\\_validation.py\", line 888, in _fit_and_score\n    estimator.fit(X_train, y_train, **fit_params)\n  File \"c:\\Users\\ldwen\\AppData\\Local\\Programs\\Python\\Python312\\Lib\\site-packages\\scikeras\\wrappers.py\", line 1501, in fit\n    super().fit(X=X, y=y, sample_weight=sample_weight, **kwargs)\n  File \"c:\\Users\\ldwen\\AppData\\Local\\Programs\\Python\\Python312\\Lib\\site-packages\\scikeras\\wrappers.py\", line 770, in fit\n    self._fit(\n  File \"c:\\Users\\ldwen\\AppData\\Local\\Programs\\Python\\Python312\\Lib\\site-packages\\scikeras\\wrappers.py\", line 936, in _fit\n    self._check_model_compatibility(y)\n  File \"c:\\Users\\ldwen\\AppData\\Local\\Programs\\Python\\Python312\\Lib\\site-packages\\scikeras\\wrappers.py\", line 559, in _check_model_compatibility\n    if self.n_outputs_expected_ != len(self.model_.outputs):\n                                       ^^^^^^^^^^^^^^^^^^^\n  File \"c:\\Users\\ldwen\\AppData\\Local\\Programs\\Python\\Python312\\Lib\\site-packages\\keras\\src\\models\\sequential.py\", line 300, in outputs\n    raise AttributeError(\nAttributeError: Sequential model 'sequential_95' has no defined outputs yet.\n\n--------------------------------------------------------------------------------\n1 fits failed with the following error:\nTraceback (most recent call last):\n  File \"c:\\Users\\ldwen\\AppData\\Local\\Programs\\Python\\Python312\\Lib\\site-packages\\sklearn\\model_selection\\_validation.py\", line 888, in _fit_and_score\n    estimator.fit(X_train, y_train, **fit_params)\n  File \"c:\\Users\\ldwen\\AppData\\Local\\Programs\\Python\\Python312\\Lib\\site-packages\\scikeras\\wrappers.py\", line 1501, in fit\n    super().fit(X=X, y=y, sample_weight=sample_weight, **kwargs)\n  File \"c:\\Users\\ldwen\\AppData\\Local\\Programs\\Python\\Python312\\Lib\\site-packages\\scikeras\\wrappers.py\", line 770, in fit\n    self._fit(\n  File \"c:\\Users\\ldwen\\AppData\\Local\\Programs\\Python\\Python312\\Lib\\site-packages\\scikeras\\wrappers.py\", line 936, in _fit\n    self._check_model_compatibility(y)\n  File \"c:\\Users\\ldwen\\AppData\\Local\\Programs\\Python\\Python312\\Lib\\site-packages\\scikeras\\wrappers.py\", line 559, in _check_model_compatibility\n    if self.n_outputs_expected_ != len(self.model_.outputs):\n                                       ^^^^^^^^^^^^^^^^^^^\n  File \"c:\\Users\\ldwen\\AppData\\Local\\Programs\\Python\\Python312\\Lib\\site-packages\\keras\\src\\models\\sequential.py\", line 300, in outputs\n    raise AttributeError(\nAttributeError: Sequential model 'sequential_96' has no defined outputs yet.\n\n--------------------------------------------------------------------------------\n1 fits failed with the following error:\nTraceback (most recent call last):\n  File \"c:\\Users\\ldwen\\AppData\\Local\\Programs\\Python\\Python312\\Lib\\site-packages\\sklearn\\model_selection\\_validation.py\", line 888, in _fit_and_score\n    estimator.fit(X_train, y_train, **fit_params)\n  File \"c:\\Users\\ldwen\\AppData\\Local\\Programs\\Python\\Python312\\Lib\\site-packages\\scikeras\\wrappers.py\", line 1501, in fit\n    super().fit(X=X, y=y, sample_weight=sample_weight, **kwargs)\n  File \"c:\\Users\\ldwen\\AppData\\Local\\Programs\\Python\\Python312\\Lib\\site-packages\\scikeras\\wrappers.py\", line 770, in fit\n    self._fit(\n  File \"c:\\Users\\ldwen\\AppData\\Local\\Programs\\Python\\Python312\\Lib\\site-packages\\scikeras\\wrappers.py\", line 936, in _fit\n    self._check_model_compatibility(y)\n  File \"c:\\Users\\ldwen\\AppData\\Local\\Programs\\Python\\Python312\\Lib\\site-packages\\scikeras\\wrappers.py\", line 559, in _check_model_compatibility\n    if self.n_outputs_expected_ != len(self.model_.outputs):\n                                       ^^^^^^^^^^^^^^^^^^^\n  File \"c:\\Users\\ldwen\\AppData\\Local\\Programs\\Python\\Python312\\Lib\\site-packages\\keras\\src\\models\\sequential.py\", line 300, in outputs\n    raise AttributeError(\nAttributeError: Sequential model 'sequential_97' has no defined outputs yet.\n\n--------------------------------------------------------------------------------\n1 fits failed with the following error:\nTraceback (most recent call last):\n  File \"c:\\Users\\ldwen\\AppData\\Local\\Programs\\Python\\Python312\\Lib\\site-packages\\sklearn\\model_selection\\_validation.py\", line 888, in _fit_and_score\n    estimator.fit(X_train, y_train, **fit_params)\n  File \"c:\\Users\\ldwen\\AppData\\Local\\Programs\\Python\\Python312\\Lib\\site-packages\\scikeras\\wrappers.py\", line 1501, in fit\n    super().fit(X=X, y=y, sample_weight=sample_weight, **kwargs)\n  File \"c:\\Users\\ldwen\\AppData\\Local\\Programs\\Python\\Python312\\Lib\\site-packages\\scikeras\\wrappers.py\", line 770, in fit\n    self._fit(\n  File \"c:\\Users\\ldwen\\AppData\\Local\\Programs\\Python\\Python312\\Lib\\site-packages\\scikeras\\wrappers.py\", line 936, in _fit\n    self._check_model_compatibility(y)\n  File \"c:\\Users\\ldwen\\AppData\\Local\\Programs\\Python\\Python312\\Lib\\site-packages\\scikeras\\wrappers.py\", line 559, in _check_model_compatibility\n    if self.n_outputs_expected_ != len(self.model_.outputs):\n                                       ^^^^^^^^^^^^^^^^^^^\n  File \"c:\\Users\\ldwen\\AppData\\Local\\Programs\\Python\\Python312\\Lib\\site-packages\\keras\\src\\models\\sequential.py\", line 300, in outputs\n    raise AttributeError(\nAttributeError: Sequential model 'sequential_98' has no defined outputs yet.\n\n--------------------------------------------------------------------------------\n1 fits failed with the following error:\nTraceback (most recent call last):\n  File \"c:\\Users\\ldwen\\AppData\\Local\\Programs\\Python\\Python312\\Lib\\site-packages\\sklearn\\model_selection\\_validation.py\", line 888, in _fit_and_score\n    estimator.fit(X_train, y_train, **fit_params)\n  File \"c:\\Users\\ldwen\\AppData\\Local\\Programs\\Python\\Python312\\Lib\\site-packages\\scikeras\\wrappers.py\", line 1501, in fit\n    super().fit(X=X, y=y, sample_weight=sample_weight, **kwargs)\n  File \"c:\\Users\\ldwen\\AppData\\Local\\Programs\\Python\\Python312\\Lib\\site-packages\\scikeras\\wrappers.py\", line 770, in fit\n    self._fit(\n  File \"c:\\Users\\ldwen\\AppData\\Local\\Programs\\Python\\Python312\\Lib\\site-packages\\scikeras\\wrappers.py\", line 936, in _fit\n    self._check_model_compatibility(y)\n  File \"c:\\Users\\ldwen\\AppData\\Local\\Programs\\Python\\Python312\\Lib\\site-packages\\scikeras\\wrappers.py\", line 559, in _check_model_compatibility\n    if self.n_outputs_expected_ != len(self.model_.outputs):\n                                       ^^^^^^^^^^^^^^^^^^^\n  File \"c:\\Users\\ldwen\\AppData\\Local\\Programs\\Python\\Python312\\Lib\\site-packages\\keras\\src\\models\\sequential.py\", line 300, in outputs\n    raise AttributeError(\nAttributeError: Sequential model 'sequential_99' has no defined outputs yet.\n\n--------------------------------------------------------------------------------\n1 fits failed with the following error:\nTraceback (most recent call last):\n  File \"c:\\Users\\ldwen\\AppData\\Local\\Programs\\Python\\Python312\\Lib\\site-packages\\sklearn\\model_selection\\_validation.py\", line 888, in _fit_and_score\n    estimator.fit(X_train, y_train, **fit_params)\n  File \"c:\\Users\\ldwen\\AppData\\Local\\Programs\\Python\\Python312\\Lib\\site-packages\\scikeras\\wrappers.py\", line 1501, in fit\n    super().fit(X=X, y=y, sample_weight=sample_weight, **kwargs)\n  File \"c:\\Users\\ldwen\\AppData\\Local\\Programs\\Python\\Python312\\Lib\\site-packages\\scikeras\\wrappers.py\", line 770, in fit\n    self._fit(\n  File \"c:\\Users\\ldwen\\AppData\\Local\\Programs\\Python\\Python312\\Lib\\site-packages\\scikeras\\wrappers.py\", line 936, in _fit\n    self._check_model_compatibility(y)\n  File \"c:\\Users\\ldwen\\AppData\\Local\\Programs\\Python\\Python312\\Lib\\site-packages\\scikeras\\wrappers.py\", line 559, in _check_model_compatibility\n    if self.n_outputs_expected_ != len(self.model_.outputs):\n                                       ^^^^^^^^^^^^^^^^^^^\n  File \"c:\\Users\\ldwen\\AppData\\Local\\Programs\\Python\\Python312\\Lib\\site-packages\\keras\\src\\models\\sequential.py\", line 300, in outputs\n    raise AttributeError(\nAttributeError: Sequential model 'sequential_100' has no defined outputs yet.\n",
     "output_type": "error",
     "traceback": [
      "\u001b[1;31m---------------------------------------------------------------------------\u001b[0m",
      "\u001b[1;31mValueError\u001b[0m                                Traceback (most recent call last)",
      "Cell \u001b[1;32mIn[27], line 2\u001b[0m\n\u001b[0;32m      1\u001b[0m grid \u001b[38;5;241m=\u001b[39m GridSearchCV(estimator\u001b[38;5;241m=\u001b[39mmodel, param_grid\u001b[38;5;241m=\u001b[39mparameters)\n\u001b[1;32m----> 2\u001b[0m grid_result \u001b[38;5;241m=\u001b[39m \u001b[43mgrid\u001b[49m\u001b[38;5;241;43m.\u001b[39;49m\u001b[43mfit\u001b[49m\u001b[43m(\u001b[49m\u001b[43mX_train\u001b[49m\u001b[43m,\u001b[49m\u001b[43m \u001b[49m\u001b[43mY_train\u001b[49m\u001b[43m)\u001b[49m\n\u001b[0;32m      3\u001b[0m \u001b[38;5;28mprint\u001b[39m(\u001b[38;5;124m\"\u001b[39m\u001b[38;5;124mBest: \u001b[39m\u001b[38;5;132;01m%f\u001b[39;00m\u001b[38;5;124m using \u001b[39m\u001b[38;5;132;01m%s\u001b[39;00m\u001b[38;5;124m\"\u001b[39m \u001b[38;5;241m%\u001b[39m (grid_result\u001b[38;5;241m.\u001b[39mbest_score_, grid_result\u001b[38;5;241m.\u001b[39mbest_params_))\n",
      "File \u001b[1;32mc:\\Users\\ldwen\\AppData\\Local\\Programs\\Python\\Python312\\Lib\\site-packages\\sklearn\\base.py:1473\u001b[0m, in \u001b[0;36m_fit_context.<locals>.decorator.<locals>.wrapper\u001b[1;34m(estimator, *args, **kwargs)\u001b[0m\n\u001b[0;32m   1466\u001b[0m     estimator\u001b[38;5;241m.\u001b[39m_validate_params()\n\u001b[0;32m   1468\u001b[0m \u001b[38;5;28;01mwith\u001b[39;00m config_context(\n\u001b[0;32m   1469\u001b[0m     skip_parameter_validation\u001b[38;5;241m=\u001b[39m(\n\u001b[0;32m   1470\u001b[0m         prefer_skip_nested_validation \u001b[38;5;129;01mor\u001b[39;00m global_skip_validation\n\u001b[0;32m   1471\u001b[0m     )\n\u001b[0;32m   1472\u001b[0m ):\n\u001b[1;32m-> 1473\u001b[0m     \u001b[38;5;28;01mreturn\u001b[39;00m \u001b[43mfit_method\u001b[49m\u001b[43m(\u001b[49m\u001b[43mestimator\u001b[49m\u001b[43m,\u001b[49m\u001b[43m \u001b[49m\u001b[38;5;241;43m*\u001b[39;49m\u001b[43margs\u001b[49m\u001b[43m,\u001b[49m\u001b[43m \u001b[49m\u001b[38;5;241;43m*\u001b[39;49m\u001b[38;5;241;43m*\u001b[39;49m\u001b[43mkwargs\u001b[49m\u001b[43m)\u001b[49m\n",
      "File \u001b[1;32mc:\\Users\\ldwen\\AppData\\Local\\Programs\\Python\\Python312\\Lib\\site-packages\\sklearn\\model_selection\\_search.py:1019\u001b[0m, in \u001b[0;36mBaseSearchCV.fit\u001b[1;34m(self, X, y, **params)\u001b[0m\n\u001b[0;32m   1013\u001b[0m     results \u001b[38;5;241m=\u001b[39m \u001b[38;5;28mself\u001b[39m\u001b[38;5;241m.\u001b[39m_format_results(\n\u001b[0;32m   1014\u001b[0m         all_candidate_params, n_splits, all_out, all_more_results\n\u001b[0;32m   1015\u001b[0m     )\n\u001b[0;32m   1017\u001b[0m     \u001b[38;5;28;01mreturn\u001b[39;00m results\n\u001b[1;32m-> 1019\u001b[0m \u001b[38;5;28;43mself\u001b[39;49m\u001b[38;5;241;43m.\u001b[39;49m\u001b[43m_run_search\u001b[49m\u001b[43m(\u001b[49m\u001b[43mevaluate_candidates\u001b[49m\u001b[43m)\u001b[49m\n\u001b[0;32m   1021\u001b[0m \u001b[38;5;66;03m# multimetric is determined here because in the case of a callable\u001b[39;00m\n\u001b[0;32m   1022\u001b[0m \u001b[38;5;66;03m# self.scoring the return type is only known after calling\u001b[39;00m\n\u001b[0;32m   1023\u001b[0m first_test_score \u001b[38;5;241m=\u001b[39m all_out[\u001b[38;5;241m0\u001b[39m][\u001b[38;5;124m\"\u001b[39m\u001b[38;5;124mtest_scores\u001b[39m\u001b[38;5;124m\"\u001b[39m]\n",
      "File \u001b[1;32mc:\\Users\\ldwen\\AppData\\Local\\Programs\\Python\\Python312\\Lib\\site-packages\\sklearn\\model_selection\\_search.py:1573\u001b[0m, in \u001b[0;36mGridSearchCV._run_search\u001b[1;34m(self, evaluate_candidates)\u001b[0m\n\u001b[0;32m   1571\u001b[0m \u001b[38;5;28;01mdef\u001b[39;00m \u001b[38;5;21m_run_search\u001b[39m(\u001b[38;5;28mself\u001b[39m, evaluate_candidates):\n\u001b[0;32m   1572\u001b[0m \u001b[38;5;250m    \u001b[39m\u001b[38;5;124;03m\"\"\"Search all candidates in param_grid\"\"\"\u001b[39;00m\n\u001b[1;32m-> 1573\u001b[0m     \u001b[43mevaluate_candidates\u001b[49m\u001b[43m(\u001b[49m\u001b[43mParameterGrid\u001b[49m\u001b[43m(\u001b[49m\u001b[38;5;28;43mself\u001b[39;49m\u001b[38;5;241;43m.\u001b[39;49m\u001b[43mparam_grid\u001b[49m\u001b[43m)\u001b[49m\u001b[43m)\u001b[49m\n",
      "File \u001b[1;32mc:\\Users\\ldwen\\AppData\\Local\\Programs\\Python\\Python312\\Lib\\site-packages\\sklearn\\model_selection\\_search.py:996\u001b[0m, in \u001b[0;36mBaseSearchCV.fit.<locals>.evaluate_candidates\u001b[1;34m(candidate_params, cv, more_results)\u001b[0m\n\u001b[0;32m    989\u001b[0m \u001b[38;5;28;01melif\u001b[39;00m \u001b[38;5;28mlen\u001b[39m(out) \u001b[38;5;241m!=\u001b[39m n_candidates \u001b[38;5;241m*\u001b[39m n_splits:\n\u001b[0;32m    990\u001b[0m     \u001b[38;5;28;01mraise\u001b[39;00m \u001b[38;5;167;01mValueError\u001b[39;00m(\n\u001b[0;32m    991\u001b[0m         \u001b[38;5;124m\"\u001b[39m\u001b[38;5;124mcv.split and cv.get_n_splits returned \u001b[39m\u001b[38;5;124m\"\u001b[39m\n\u001b[0;32m    992\u001b[0m         \u001b[38;5;124m\"\u001b[39m\u001b[38;5;124minconsistent results. Expected \u001b[39m\u001b[38;5;132;01m{}\u001b[39;00m\u001b[38;5;124m \u001b[39m\u001b[38;5;124m\"\u001b[39m\n\u001b[0;32m    993\u001b[0m         \u001b[38;5;124m\"\u001b[39m\u001b[38;5;124msplits, got \u001b[39m\u001b[38;5;132;01m{}\u001b[39;00m\u001b[38;5;124m\"\u001b[39m\u001b[38;5;241m.\u001b[39mformat(n_splits, \u001b[38;5;28mlen\u001b[39m(out) \u001b[38;5;241m/\u001b[39m\u001b[38;5;241m/\u001b[39m n_candidates)\n\u001b[0;32m    994\u001b[0m     )\n\u001b[1;32m--> 996\u001b[0m \u001b[43m_warn_or_raise_about_fit_failures\u001b[49m\u001b[43m(\u001b[49m\u001b[43mout\u001b[49m\u001b[43m,\u001b[49m\u001b[43m \u001b[49m\u001b[38;5;28;43mself\u001b[39;49m\u001b[38;5;241;43m.\u001b[39;49m\u001b[43merror_score\u001b[49m\u001b[43m)\u001b[49m\n\u001b[0;32m    998\u001b[0m \u001b[38;5;66;03m# For callable self.scoring, the return type is only know after\u001b[39;00m\n\u001b[0;32m    999\u001b[0m \u001b[38;5;66;03m# calling. If the return type is a dictionary, the error scores\u001b[39;00m\n\u001b[0;32m   1000\u001b[0m \u001b[38;5;66;03m# can now be inserted with the correct key. The type checking\u001b[39;00m\n\u001b[0;32m   1001\u001b[0m \u001b[38;5;66;03m# of out will be done in `_insert_error_scores`.\u001b[39;00m\n\u001b[0;32m   1002\u001b[0m \u001b[38;5;28;01mif\u001b[39;00m \u001b[38;5;28mcallable\u001b[39m(\u001b[38;5;28mself\u001b[39m\u001b[38;5;241m.\u001b[39mscoring):\n",
      "File \u001b[1;32mc:\\Users\\ldwen\\AppData\\Local\\Programs\\Python\\Python312\\Lib\\site-packages\\sklearn\\model_selection\\_validation.py:529\u001b[0m, in \u001b[0;36m_warn_or_raise_about_fit_failures\u001b[1;34m(results, error_score)\u001b[0m\n\u001b[0;32m    522\u001b[0m \u001b[38;5;28;01mif\u001b[39;00m num_failed_fits \u001b[38;5;241m==\u001b[39m num_fits:\n\u001b[0;32m    523\u001b[0m     all_fits_failed_message \u001b[38;5;241m=\u001b[39m (\n\u001b[0;32m    524\u001b[0m         \u001b[38;5;124mf\u001b[39m\u001b[38;5;124m\"\u001b[39m\u001b[38;5;130;01m\\n\u001b[39;00m\u001b[38;5;124mAll the \u001b[39m\u001b[38;5;132;01m{\u001b[39;00mnum_fits\u001b[38;5;132;01m}\u001b[39;00m\u001b[38;5;124m fits failed.\u001b[39m\u001b[38;5;130;01m\\n\u001b[39;00m\u001b[38;5;124m\"\u001b[39m\n\u001b[0;32m    525\u001b[0m         \u001b[38;5;124m\"\u001b[39m\u001b[38;5;124mIt is very likely that your model is misconfigured.\u001b[39m\u001b[38;5;130;01m\\n\u001b[39;00m\u001b[38;5;124m\"\u001b[39m\n\u001b[0;32m    526\u001b[0m         \u001b[38;5;124m\"\u001b[39m\u001b[38;5;124mYou can try to debug the error by setting error_score=\u001b[39m\u001b[38;5;124m'\u001b[39m\u001b[38;5;124mraise\u001b[39m\u001b[38;5;124m'\u001b[39m\u001b[38;5;124m.\u001b[39m\u001b[38;5;130;01m\\n\u001b[39;00m\u001b[38;5;130;01m\\n\u001b[39;00m\u001b[38;5;124m\"\u001b[39m\n\u001b[0;32m    527\u001b[0m         \u001b[38;5;124mf\u001b[39m\u001b[38;5;124m\"\u001b[39m\u001b[38;5;124mBelow are more details about the failures:\u001b[39m\u001b[38;5;130;01m\\n\u001b[39;00m\u001b[38;5;132;01m{\u001b[39;00mfit_errors_summary\u001b[38;5;132;01m}\u001b[39;00m\u001b[38;5;124m\"\u001b[39m\n\u001b[0;32m    528\u001b[0m     )\n\u001b[1;32m--> 529\u001b[0m     \u001b[38;5;28;01mraise\u001b[39;00m \u001b[38;5;167;01mValueError\u001b[39;00m(all_fits_failed_message)\n\u001b[0;32m    531\u001b[0m \u001b[38;5;28;01melse\u001b[39;00m:\n\u001b[0;32m    532\u001b[0m     some_fits_failed_message \u001b[38;5;241m=\u001b[39m (\n\u001b[0;32m    533\u001b[0m         \u001b[38;5;124mf\u001b[39m\u001b[38;5;124m\"\u001b[39m\u001b[38;5;130;01m\\n\u001b[39;00m\u001b[38;5;132;01m{\u001b[39;00mnum_failed_fits\u001b[38;5;132;01m}\u001b[39;00m\u001b[38;5;124m fits failed out of a total of \u001b[39m\u001b[38;5;132;01m{\u001b[39;00mnum_fits\u001b[38;5;132;01m}\u001b[39;00m\u001b[38;5;124m.\u001b[39m\u001b[38;5;130;01m\\n\u001b[39;00m\u001b[38;5;124m\"\u001b[39m\n\u001b[0;32m    534\u001b[0m         \u001b[38;5;124m\"\u001b[39m\u001b[38;5;124mThe score on these train-test partitions for these parameters\u001b[39m\u001b[38;5;124m\"\u001b[39m\n\u001b[1;32m   (...)\u001b[0m\n\u001b[0;32m    538\u001b[0m         \u001b[38;5;124mf\u001b[39m\u001b[38;5;124m\"\u001b[39m\u001b[38;5;124mBelow are more details about the failures:\u001b[39m\u001b[38;5;130;01m\\n\u001b[39;00m\u001b[38;5;132;01m{\u001b[39;00mfit_errors_summary\u001b[38;5;132;01m}\u001b[39;00m\u001b[38;5;124m\"\u001b[39m\n\u001b[0;32m    539\u001b[0m     )\n",
      "\u001b[1;31mValueError\u001b[0m: \nAll the 10 fits failed.\nIt is very likely that your model is misconfigured.\nYou can try to debug the error by setting error_score='raise'.\n\nBelow are more details about the failures:\n--------------------------------------------------------------------------------\n1 fits failed with the following error:\nTraceback (most recent call last):\n  File \"c:\\Users\\ldwen\\AppData\\Local\\Programs\\Python\\Python312\\Lib\\site-packages\\sklearn\\model_selection\\_validation.py\", line 888, in _fit_and_score\n    estimator.fit(X_train, y_train, **fit_params)\n  File \"c:\\Users\\ldwen\\AppData\\Local\\Programs\\Python\\Python312\\Lib\\site-packages\\scikeras\\wrappers.py\", line 1501, in fit\n    super().fit(X=X, y=y, sample_weight=sample_weight, **kwargs)\n  File \"c:\\Users\\ldwen\\AppData\\Local\\Programs\\Python\\Python312\\Lib\\site-packages\\scikeras\\wrappers.py\", line 770, in fit\n    self._fit(\n  File \"c:\\Users\\ldwen\\AppData\\Local\\Programs\\Python\\Python312\\Lib\\site-packages\\scikeras\\wrappers.py\", line 936, in _fit\n    self._check_model_compatibility(y)\n  File \"c:\\Users\\ldwen\\AppData\\Local\\Programs\\Python\\Python312\\Lib\\site-packages\\scikeras\\wrappers.py\", line 559, in _check_model_compatibility\n    if self.n_outputs_expected_ != len(self.model_.outputs):\n                                       ^^^^^^^^^^^^^^^^^^^\n  File \"c:\\Users\\ldwen\\AppData\\Local\\Programs\\Python\\Python312\\Lib\\site-packages\\keras\\src\\models\\sequential.py\", line 300, in outputs\n    raise AttributeError(\nAttributeError: Sequential model 'sequential_91' has no defined outputs yet.\n\n--------------------------------------------------------------------------------\n1 fits failed with the following error:\nTraceback (most recent call last):\n  File \"c:\\Users\\ldwen\\AppData\\Local\\Programs\\Python\\Python312\\Lib\\site-packages\\sklearn\\model_selection\\_validation.py\", line 888, in _fit_and_score\n    estimator.fit(X_train, y_train, **fit_params)\n  File \"c:\\Users\\ldwen\\AppData\\Local\\Programs\\Python\\Python312\\Lib\\site-packages\\scikeras\\wrappers.py\", line 1501, in fit\n    super().fit(X=X, y=y, sample_weight=sample_weight, **kwargs)\n  File \"c:\\Users\\ldwen\\AppData\\Local\\Programs\\Python\\Python312\\Lib\\site-packages\\scikeras\\wrappers.py\", line 770, in fit\n    self._fit(\n  File \"c:\\Users\\ldwen\\AppData\\Local\\Programs\\Python\\Python312\\Lib\\site-packages\\scikeras\\wrappers.py\", line 936, in _fit\n    self._check_model_compatibility(y)\n  File \"c:\\Users\\ldwen\\AppData\\Local\\Programs\\Python\\Python312\\Lib\\site-packages\\scikeras\\wrappers.py\", line 559, in _check_model_compatibility\n    if self.n_outputs_expected_ != len(self.model_.outputs):\n                                       ^^^^^^^^^^^^^^^^^^^\n  File \"c:\\Users\\ldwen\\AppData\\Local\\Programs\\Python\\Python312\\Lib\\site-packages\\keras\\src\\models\\sequential.py\", line 300, in outputs\n    raise AttributeError(\nAttributeError: Sequential model 'sequential_92' has no defined outputs yet.\n\n--------------------------------------------------------------------------------\n1 fits failed with the following error:\nTraceback (most recent call last):\n  File \"c:\\Users\\ldwen\\AppData\\Local\\Programs\\Python\\Python312\\Lib\\site-packages\\sklearn\\model_selection\\_validation.py\", line 888, in _fit_and_score\n    estimator.fit(X_train, y_train, **fit_params)\n  File \"c:\\Users\\ldwen\\AppData\\Local\\Programs\\Python\\Python312\\Lib\\site-packages\\scikeras\\wrappers.py\", line 1501, in fit\n    super().fit(X=X, y=y, sample_weight=sample_weight, **kwargs)\n  File \"c:\\Users\\ldwen\\AppData\\Local\\Programs\\Python\\Python312\\Lib\\site-packages\\scikeras\\wrappers.py\", line 770, in fit\n    self._fit(\n  File \"c:\\Users\\ldwen\\AppData\\Local\\Programs\\Python\\Python312\\Lib\\site-packages\\scikeras\\wrappers.py\", line 936, in _fit\n    self._check_model_compatibility(y)\n  File \"c:\\Users\\ldwen\\AppData\\Local\\Programs\\Python\\Python312\\Lib\\site-packages\\scikeras\\wrappers.py\", line 559, in _check_model_compatibility\n    if self.n_outputs_expected_ != len(self.model_.outputs):\n                                       ^^^^^^^^^^^^^^^^^^^\n  File \"c:\\Users\\ldwen\\AppData\\Local\\Programs\\Python\\Python312\\Lib\\site-packages\\keras\\src\\models\\sequential.py\", line 300, in outputs\n    raise AttributeError(\nAttributeError: Sequential model 'sequential_93' has no defined outputs yet.\n\n--------------------------------------------------------------------------------\n1 fits failed with the following error:\nTraceback (most recent call last):\n  File \"c:\\Users\\ldwen\\AppData\\Local\\Programs\\Python\\Python312\\Lib\\site-packages\\sklearn\\model_selection\\_validation.py\", line 888, in _fit_and_score\n    estimator.fit(X_train, y_train, **fit_params)\n  File \"c:\\Users\\ldwen\\AppData\\Local\\Programs\\Python\\Python312\\Lib\\site-packages\\scikeras\\wrappers.py\", line 1501, in fit\n    super().fit(X=X, y=y, sample_weight=sample_weight, **kwargs)\n  File \"c:\\Users\\ldwen\\AppData\\Local\\Programs\\Python\\Python312\\Lib\\site-packages\\scikeras\\wrappers.py\", line 770, in fit\n    self._fit(\n  File \"c:\\Users\\ldwen\\AppData\\Local\\Programs\\Python\\Python312\\Lib\\site-packages\\scikeras\\wrappers.py\", line 936, in _fit\n    self._check_model_compatibility(y)\n  File \"c:\\Users\\ldwen\\AppData\\Local\\Programs\\Python\\Python312\\Lib\\site-packages\\scikeras\\wrappers.py\", line 559, in _check_model_compatibility\n    if self.n_outputs_expected_ != len(self.model_.outputs):\n                                       ^^^^^^^^^^^^^^^^^^^\n  File \"c:\\Users\\ldwen\\AppData\\Local\\Programs\\Python\\Python312\\Lib\\site-packages\\keras\\src\\models\\sequential.py\", line 300, in outputs\n    raise AttributeError(\nAttributeError: Sequential model 'sequential_94' has no defined outputs yet.\n\n--------------------------------------------------------------------------------\n1 fits failed with the following error:\nTraceback (most recent call last):\n  File \"c:\\Users\\ldwen\\AppData\\Local\\Programs\\Python\\Python312\\Lib\\site-packages\\sklearn\\model_selection\\_validation.py\", line 888, in _fit_and_score\n    estimator.fit(X_train, y_train, **fit_params)\n  File \"c:\\Users\\ldwen\\AppData\\Local\\Programs\\Python\\Python312\\Lib\\site-packages\\scikeras\\wrappers.py\", line 1501, in fit\n    super().fit(X=X, y=y, sample_weight=sample_weight, **kwargs)\n  File \"c:\\Users\\ldwen\\AppData\\Local\\Programs\\Python\\Python312\\Lib\\site-packages\\scikeras\\wrappers.py\", line 770, in fit\n    self._fit(\n  File \"c:\\Users\\ldwen\\AppData\\Local\\Programs\\Python\\Python312\\Lib\\site-packages\\scikeras\\wrappers.py\", line 936, in _fit\n    self._check_model_compatibility(y)\n  File \"c:\\Users\\ldwen\\AppData\\Local\\Programs\\Python\\Python312\\Lib\\site-packages\\scikeras\\wrappers.py\", line 559, in _check_model_compatibility\n    if self.n_outputs_expected_ != len(self.model_.outputs):\n                                       ^^^^^^^^^^^^^^^^^^^\n  File \"c:\\Users\\ldwen\\AppData\\Local\\Programs\\Python\\Python312\\Lib\\site-packages\\keras\\src\\models\\sequential.py\", line 300, in outputs\n    raise AttributeError(\nAttributeError: Sequential model 'sequential_95' has no defined outputs yet.\n\n--------------------------------------------------------------------------------\n1 fits failed with the following error:\nTraceback (most recent call last):\n  File \"c:\\Users\\ldwen\\AppData\\Local\\Programs\\Python\\Python312\\Lib\\site-packages\\sklearn\\model_selection\\_validation.py\", line 888, in _fit_and_score\n    estimator.fit(X_train, y_train, **fit_params)\n  File \"c:\\Users\\ldwen\\AppData\\Local\\Programs\\Python\\Python312\\Lib\\site-packages\\scikeras\\wrappers.py\", line 1501, in fit\n    super().fit(X=X, y=y, sample_weight=sample_weight, **kwargs)\n  File \"c:\\Users\\ldwen\\AppData\\Local\\Programs\\Python\\Python312\\Lib\\site-packages\\scikeras\\wrappers.py\", line 770, in fit\n    self._fit(\n  File \"c:\\Users\\ldwen\\AppData\\Local\\Programs\\Python\\Python312\\Lib\\site-packages\\scikeras\\wrappers.py\", line 936, in _fit\n    self._check_model_compatibility(y)\n  File \"c:\\Users\\ldwen\\AppData\\Local\\Programs\\Python\\Python312\\Lib\\site-packages\\scikeras\\wrappers.py\", line 559, in _check_model_compatibility\n    if self.n_outputs_expected_ != len(self.model_.outputs):\n                                       ^^^^^^^^^^^^^^^^^^^\n  File \"c:\\Users\\ldwen\\AppData\\Local\\Programs\\Python\\Python312\\Lib\\site-packages\\keras\\src\\models\\sequential.py\", line 300, in outputs\n    raise AttributeError(\nAttributeError: Sequential model 'sequential_96' has no defined outputs yet.\n\n--------------------------------------------------------------------------------\n1 fits failed with the following error:\nTraceback (most recent call last):\n  File \"c:\\Users\\ldwen\\AppData\\Local\\Programs\\Python\\Python312\\Lib\\site-packages\\sklearn\\model_selection\\_validation.py\", line 888, in _fit_and_score\n    estimator.fit(X_train, y_train, **fit_params)\n  File \"c:\\Users\\ldwen\\AppData\\Local\\Programs\\Python\\Python312\\Lib\\site-packages\\scikeras\\wrappers.py\", line 1501, in fit\n    super().fit(X=X, y=y, sample_weight=sample_weight, **kwargs)\n  File \"c:\\Users\\ldwen\\AppData\\Local\\Programs\\Python\\Python312\\Lib\\site-packages\\scikeras\\wrappers.py\", line 770, in fit\n    self._fit(\n  File \"c:\\Users\\ldwen\\AppData\\Local\\Programs\\Python\\Python312\\Lib\\site-packages\\scikeras\\wrappers.py\", line 936, in _fit\n    self._check_model_compatibility(y)\n  File \"c:\\Users\\ldwen\\AppData\\Local\\Programs\\Python\\Python312\\Lib\\site-packages\\scikeras\\wrappers.py\", line 559, in _check_model_compatibility\n    if self.n_outputs_expected_ != len(self.model_.outputs):\n                                       ^^^^^^^^^^^^^^^^^^^\n  File \"c:\\Users\\ldwen\\AppData\\Local\\Programs\\Python\\Python312\\Lib\\site-packages\\keras\\src\\models\\sequential.py\", line 300, in outputs\n    raise AttributeError(\nAttributeError: Sequential model 'sequential_97' has no defined outputs yet.\n\n--------------------------------------------------------------------------------\n1 fits failed with the following error:\nTraceback (most recent call last):\n  File \"c:\\Users\\ldwen\\AppData\\Local\\Programs\\Python\\Python312\\Lib\\site-packages\\sklearn\\model_selection\\_validation.py\", line 888, in _fit_and_score\n    estimator.fit(X_train, y_train, **fit_params)\n  File \"c:\\Users\\ldwen\\AppData\\Local\\Programs\\Python\\Python312\\Lib\\site-packages\\scikeras\\wrappers.py\", line 1501, in fit\n    super().fit(X=X, y=y, sample_weight=sample_weight, **kwargs)\n  File \"c:\\Users\\ldwen\\AppData\\Local\\Programs\\Python\\Python312\\Lib\\site-packages\\scikeras\\wrappers.py\", line 770, in fit\n    self._fit(\n  File \"c:\\Users\\ldwen\\AppData\\Local\\Programs\\Python\\Python312\\Lib\\site-packages\\scikeras\\wrappers.py\", line 936, in _fit\n    self._check_model_compatibility(y)\n  File \"c:\\Users\\ldwen\\AppData\\Local\\Programs\\Python\\Python312\\Lib\\site-packages\\scikeras\\wrappers.py\", line 559, in _check_model_compatibility\n    if self.n_outputs_expected_ != len(self.model_.outputs):\n                                       ^^^^^^^^^^^^^^^^^^^\n  File \"c:\\Users\\ldwen\\AppData\\Local\\Programs\\Python\\Python312\\Lib\\site-packages\\keras\\src\\models\\sequential.py\", line 300, in outputs\n    raise AttributeError(\nAttributeError: Sequential model 'sequential_98' has no defined outputs yet.\n\n--------------------------------------------------------------------------------\n1 fits failed with the following error:\nTraceback (most recent call last):\n  File \"c:\\Users\\ldwen\\AppData\\Local\\Programs\\Python\\Python312\\Lib\\site-packages\\sklearn\\model_selection\\_validation.py\", line 888, in _fit_and_score\n    estimator.fit(X_train, y_train, **fit_params)\n  File \"c:\\Users\\ldwen\\AppData\\Local\\Programs\\Python\\Python312\\Lib\\site-packages\\scikeras\\wrappers.py\", line 1501, in fit\n    super().fit(X=X, y=y, sample_weight=sample_weight, **kwargs)\n  File \"c:\\Users\\ldwen\\AppData\\Local\\Programs\\Python\\Python312\\Lib\\site-packages\\scikeras\\wrappers.py\", line 770, in fit\n    self._fit(\n  File \"c:\\Users\\ldwen\\AppData\\Local\\Programs\\Python\\Python312\\Lib\\site-packages\\scikeras\\wrappers.py\", line 936, in _fit\n    self._check_model_compatibility(y)\n  File \"c:\\Users\\ldwen\\AppData\\Local\\Programs\\Python\\Python312\\Lib\\site-packages\\scikeras\\wrappers.py\", line 559, in _check_model_compatibility\n    if self.n_outputs_expected_ != len(self.model_.outputs):\n                                       ^^^^^^^^^^^^^^^^^^^\n  File \"c:\\Users\\ldwen\\AppData\\Local\\Programs\\Python\\Python312\\Lib\\site-packages\\keras\\src\\models\\sequential.py\", line 300, in outputs\n    raise AttributeError(\nAttributeError: Sequential model 'sequential_99' has no defined outputs yet.\n\n--------------------------------------------------------------------------------\n1 fits failed with the following error:\nTraceback (most recent call last):\n  File \"c:\\Users\\ldwen\\AppData\\Local\\Programs\\Python\\Python312\\Lib\\site-packages\\sklearn\\model_selection\\_validation.py\", line 888, in _fit_and_score\n    estimator.fit(X_train, y_train, **fit_params)\n  File \"c:\\Users\\ldwen\\AppData\\Local\\Programs\\Python\\Python312\\Lib\\site-packages\\scikeras\\wrappers.py\", line 1501, in fit\n    super().fit(X=X, y=y, sample_weight=sample_weight, **kwargs)\n  File \"c:\\Users\\ldwen\\AppData\\Local\\Programs\\Python\\Python312\\Lib\\site-packages\\scikeras\\wrappers.py\", line 770, in fit\n    self._fit(\n  File \"c:\\Users\\ldwen\\AppData\\Local\\Programs\\Python\\Python312\\Lib\\site-packages\\scikeras\\wrappers.py\", line 936, in _fit\n    self._check_model_compatibility(y)\n  File \"c:\\Users\\ldwen\\AppData\\Local\\Programs\\Python\\Python312\\Lib\\site-packages\\scikeras\\wrappers.py\", line 559, in _check_model_compatibility\n    if self.n_outputs_expected_ != len(self.model_.outputs):\n                                       ^^^^^^^^^^^^^^^^^^^\n  File \"c:\\Users\\ldwen\\AppData\\Local\\Programs\\Python\\Python312\\Lib\\site-packages\\keras\\src\\models\\sequential.py\", line 300, in outputs\n    raise AttributeError(\nAttributeError: Sequential model 'sequential_100' has no defined outputs yet.\n"
     ]
    }
   ],
   "source": [
    "grid = GridSearchCV(estimator=model, param_grid=parameters)\n",
    "grid_result = grid.fit(X_train, Y_train)\n",
    "print(\"Best: %f using %s\" % (grid_result.best_score_, grid_result.best_params_))"
   ]
  }
 ],
 "metadata": {
  "kernelspec": {
   "display_name": "Python 3",
   "language": "python",
   "name": "python3"
  },
  "language_info": {
   "codemirror_mode": {
    "name": "ipython",
    "version": 3
   },
   "file_extension": ".py",
   "mimetype": "text/x-python",
   "name": "python",
   "nbconvert_exporter": "python",
   "pygments_lexer": "ipython3",
   "version": "3.12.7"
  }
 },
 "nbformat": 4,
 "nbformat_minor": 2
}
